Workbook

Sheet Operaciones
A1: Fecha | B1: Operacion | C1: Tipo de activo | D1: Activo | E1: Nominales | F1: Precio | G1: Valor USD | H1: Precio ARS | I1: Valor ARS | K1: Deposito cash | L1: Retiro Cash | M1: Invertido | R1: Compra | T1: Lecaps | V1: AL29
A2: 45580 | B2: Retiro/Ingreso | K2: 150000 | M2: =K2-L2 -> 150000 | R2: Venta | T2: CER | V2: AL30
A3: 45581 | B3: Compra | C3: Soberano USD | D3: AL30 | E3: 1000 | F3: 63.26 | G3: =F3*E3 -> 63260 | H3: =F3*VLOOKUP(A3,'Precios'!$A$3:$AA$601,27) -> 72369.44 | I3: =G3*VLOOKUP(A3,'Precios'!$A$3:$AA$601,27) -> 72369440 | M3: =M2+K3-L3 -> 150000 | R3: Dividendos | T3: Soberano USD | V3: AL35
A4: 45581 | B4: Compra | C4: Soberano USD | D4: AL41 | E4: 900 | F4: 52.7 | G4: =F4*E4 -> 47430 | H4: =F4*VLOOKUP(A4,'Precios'!$A$3:$AA$601,27) -> 60288.8 | I4: =G4*VLOOKUP(A4,'Precios'!$A$3:$AA$601,27) -> 54259920 | M4: =M3+K4-L4 -> 150000 | R4: Amortización
A5: 45585 | B5: Venta | C5: Soberano USD | D5: AL41 | E5: 400 | F5: 52.7 | G5: =F5*E5 -> 21080 | H5: =F5*VLOOKUP(A5,'Precios'!$A$3:$AA$601,27) -> 60394.2 | I5: =G5*VLOOKUP(A5,'Precios'!$A$3:$AA$601,27) -> 24157680 | M5: =M4+K5-L5 -> 150000 | R5: Retiro/Ingreso
A6: 45582 | B6: Compra | C6: Soberano USD | D6: GD35 | E6: 200 | F6: 50 | G6: =F6*E6 -> 10000 | H6: =F6*VLOOKUP(A6,'Precios'!$A$3:$AA$601,27) -> 57250 | I6: =G6*VLOOKUP(A6,'Precios'!$A$3:$AA$601,27) -> 11450000 | M6: =M5+K6-L6 -> 150000
A7: 45583 | B7: Compra | C7: Soberano USD | D7: AL41 | E7: 100 | F7: 52.7 | G7: =F7*E7 -> 5270 | H7: =F7*VLOOKUP(A7,'Precios'!$A$3:$AA$601,27) -> 60394.2 | I7: =G7*VLOOKUP(A7,'Precios'!$A$3:$AA$601,27) -> 6039420 | M7: =M6+K7-L7 -> 150000
A8: 45584 | B8: Venta | C8: Soberano USD | D8: AL41 | E8: 600 | F8: 52.7 | G8: =F8*E8 -> 31620 | H8: =F8*VLOOKUP(A8,'Precios'!$A$3:$AA$601,27) -> 60394.2 | I8: =G8*VLOOKUP(A8,'Precios'!$A$3:$AA$601,27) -> 36236520 | M8: =M7+K8-L8 -> 150000
A9: 45665 | B9: Amortización | C9: Soberano USD | D9: AL30 | G9: 8000 | H9: =F9*VLOOKUP(A9,'Precios'!$A$3:$AA$601,27) -> 0 | I9: =G9*VLOOKUP(A9,'Precios'!$A$3:$AA$601,27) -> 9584000 | M9: =M8+K9-L9 -> 150000
A10: 45665 | B10: Amortización | C10: Soberano USD | D10: GD35 | G10: 8000 | H10: =F10*VLOOKUP(A10,'Precios'!$A$3:$AA$601,27) -> 0 | I10: =G10*VLOOKUP(A10,'Precios'!$A$3:$AA$601,27) -> 9584000 | M10: =M9+K10-L10 -> 150000
A11: 45665 | B11: Retiro/Ingreso | L11: 16000 | M11: =M10+K11-L11 -> 134000
A12: 45665 | B12: Cupon | C12: Soberano USD | D12: AL30 | G12: 375 | H12: =F12*VLOOKUP(A12,'Precios'!$A$3:$AA$601,27) -> 0 | I12: =G12*VLOOKUP(A12,'Precios'!$A$3:$AA$601,27) -> 449250 | M12: =M11+K12-L12 -> 134000
A13: 45665 | B13: Compra | C13: Soberano USD | D13: AL41 | E13: 300 | F13: 54 | G13: =E13*F13 -> 16200 | H13: =F13*VLOOKUP(A13,'Precios'!$A$3:$AA$601,27) -> 64692 | I13: =G13*VLOOKUP(A13,'Precios'!$A$3:$AA$601,27) -> 19407600 | M13: =M12+K13-L13 -> 134000
A14: 45667 | B14: Venta | C14: Soberano USD | D14: AL30 | E14: 1000 | F14: 68.5 | G14: =F14*E14 -> 68500 | H14: =F14*VLOOKUP(A14,'Precios'!$A$3:$AA$601,27) -> 82200 | I14: =G14*VLOOKUP(A14,'Precios'!$A$3:$AA$601,27) -> 82200000 | M14: =M13+K14-L14 -> 134000
A15: 45669 | B15: Compra | C15: Soberano USD | D15: AL29 | E15: 1000 | F15: 68.5 | G15: =F15*E15 -> 68500 | H15: =F15*VLOOKUP(A15,'Precios'!$A$3:$AA$601,27) -> 82200 | I15: =G15*VLOOKUP(A15,'Precios'!$A$3:$AA$601,27) -> 82200000 | M15: =M14+K15-L15 -> 134000
A16: 45669 | B16: Venta | C16: Soberano USD | D16: AL29 | E16: 1000 | F16: 68.5 | G16: =F16*E16 -> 68500 | H16: =F16*VLOOKUP(A16,'Precios'!$A$3:$AA$601,27) -> 82200 | I16: =G16*VLOOKUP(A16,'Precios'!$A$3:$AA$601,27) -> 82200000 | M16: =M15+K16-L16 -> 134000
A17: 45698 | B17: Compra | C17: Soberano USD | D17: AL30 | E17: 200 | F17: 64.7 | G17: =F17*E17 -> 12940 | H17: =F17*VLOOKUP(A17,'Precios'!$A$3:$AA$601,27) -> 78998.7 | I17: =G17*VLOOKUP(A17,'Precios'!$A$3:$AA$601,27) -> 15799740 | M17: =M16+K17-L17 -> 134000
A18: 45846 | B18: Amortización | C18: Soberano USD | D18: AL30 | G18: 1600 | H18: =F18*VLOOKUP(A18,'Precios'!$A$3:$AA$601,27) -> 0 | I18: =G18*VLOOKUP(A18,'Precios'!$A$3:$AA$601,27) -> 2107200 | M18: =M17+K18-L18 -> 134000
A19: 45846 | B19: Retiro/Ingreso | L19: 1600 | M19: =M18+K19-L19 -> 132400
A20: 45846 | B20: Cupon | C20: Soberano USD | D20: AL30 | G20: 75 | H20: =F20*VLOOKUP(A20,'Precios'!$A$3:$AA$601,27) -> 0 | I20: =G20*VLOOKUP(A20,'Precios'!$A$3:$AA$601,27) -> 98775 | M20: =M19+K20-L20 -> 132400
A21: 45846 | B21: Cupon | C21: Soberano USD | D21: AL41 | G21: =1575/2 -> 787.5 | H21: =F21*VLOOKUP(A21,'Precios'!$A$3:$AA$601,27) -> 0 | I21: =G21*VLOOKUP(A21,'Precios'!$A$3:$AA$601,27) -> 1037137.5 | M21: =M20+K21-L21 -> 132400
A22: 45847 | B22: Compra | C22: Soberano USD | D22: AL41 | E22: 300 | F22: 59 | G22: =F22*E22 -> 17700 | H22: =F22*VLOOKUP(A22,'Precios'!$A$3:$AA$601,27) -> 77703 | I22: =G22*VLOOKUP(A22,'Precios'!$A$3:$AA$601,27) -> 23310900 | M22: =M21+K22-L22 -> 132400
A23: 45848 | B23: Compra | C23: Soberano USD | D23: AL30 | E23: 600 | F23: 60.7 | G23: =F23*E23 -> 36420 | H23: =F23*VLOOKUP(A23,'Precios'!$A$3:$AA$601,27) -> 80002.6 | I23: =G23*VLOOKUP(A23,'Precios'!$A$3:$AA$601,27) -> 48001560 | M23: =M22+K23-L23 -> 132400
A24: 45863 | B24: Retiro/Ingreso | L24: 10000 | M24: =M23+K24-L24 -> 122400
A25: 45879 | B25: Venta | C25: Soberano USD | D25: AL30 | E25: 800 | F25: 58 | G25: =F25*E25 -> 46400 | H25: =F25*VLOOKUP(A25,'Precios'!$A$3:$AA$601,27) -> 77662 | I25: =G25*VLOOKUP(A25,'Precios'!$A$3:$AA$601,27) -> 62129600 | M25: =M24+K25-L25 -> 122400
A26: 45910 | B26: Compra | C26: Soberano USD | D26: AL35 | E26: 400 | F26: 55 | G26: =F26*E26 -> 22000 | H26: =F26*VLOOKUP(A26,'Precios'!$A$3:$AA$601,27) -> 74855 | I26: =G26*VLOOKUP(A26,'Precios'!$A$3:$AA$601,27) -> 29942000 | M26: =M25+K26-L26 -> 122400
A27: 45912 | B27: Venta | C27: Soberano USD | D27: AL35 | E27: 200 | F27: 54 | G27: =F27*E27 -> 10800 | H27: =F27*VLOOKUP(A27,'Precios'!$A$3:$AA$601,27) -> 73602 | I27: =G27*VLOOKUP(A27,'Precios'!$A$3:$AA$601,27) -> 14720400 | M27: =M26+K27-L27 -> 122400
A28: 45912 | B28: Retiro/Ingreso | L28: 5000 | M28: =M27+K28-L28 -> 117400
A29: 45913 | B29: Compra | C29: Soberano USD | D29: AL41 | E29: 300 | F29: 50 | G29: =F29*E29 -> 15000 | H29: =F29*VLOOKUP(A29,'Precios'!$A$3:$AA$601,27) -> 68150 | I29: =G29*VLOOKUP(A29,'Precios'!$A$3:$AA$601,27) -> 20445000 | M29: =M28+K29-L29 -> 117400
A30: 45914 | B30: Amortización | C30: Soberano USD | D30: AL41 | G30: 5000 | H30: =F30*VLOOKUP(A30,'Precios'!$A$3:$AA$601,27) -> 0 | I30: =G30*VLOOKUP(A30,'Precios'!$A$3:$AA$601,27) -> 6815000 | M30: =M29+K30-L30 -> 117400

Sheet Precios
A1: Fecha | B1: GD29 | C1: GD30 | D1: GD35 | E1: GD38 | F1: GD41 | G1: GD46 | H1: AL29 | I1: AL30 | J1: AL35 | K1: AE38 | L1: AL41 | M1: BPA7 | N1: BPOB7 | O1: BPC7 | P1: BPD7 | Q1: BPJ5 | R1: BPY26 | S1: PNXCO | T1: TTC9 | U1: BPC7C | V1: BPD7C | W1: BPJ5C | X1: BPY6C | Y1: BPO8 | Z1: BPO8C | AA1: ARS
A2: Precio Actual | B2: 60.5 | C2: 58.08 | D2: 57.62 | E2: 62.3 | F2: 54.6 | G2: 55 | H2: 58 | I2: 54.84 | J2: 54.32 | K2: 55.98 | L2: 45 | N2: 97.6 | O2: 91.5 | P2: 89.92 | R2: 101.9 | T2: 94.99 | U2: 90.17 | V2: 87.83 | W2: 0 | X2: 99.94 | Y2: 67.04 | Z2: 65.67 | AA2: 1400
A3: 45569 | B3: =B4-0.1 -> 71.4 | C3: =C4-0.1 -> 63.8 | D3: =D4-0.1 -> 55.71 | E3: =E4-0.1 -> 60.17 | F3: =F4-0.1 -> 51.5 | G3: =G4-0.1 -> 57.92 | H3: =H4-0.1 -> 70.26 | I3: =I4-0.1 -> 62.06 | ... X3: =X4-0.1 -> 88.21 | AA3: 1132
A4: 45570 | B4: =B5-0.1 -> 71.5 | C4: =C5-0.1 -> 63.9 | D4: =D5-0.1 -> 55.81 | E4: =E5-0.1 -> 60.27 | F4: =F5-0.1 -> 51.6 | G4: =G5-0.1 -> 58.02 | H4: =H5-0.1 -> 70.36 | I4: =I5-0.1 -> 62.16 | ... X4: =X5-0.1 -> 88.31 | AA4: =AA3+1 -> 1133
A5: 45571 | B5: =B6-0.1 -> 71.6 | C5: =C6-0.1 -> 64 | D5: =D6-0.1 -> 55.91 | E5: =E6-0.1 -> 60.37 | F5: =F6-0.1 -> 51.7 | G5: =G6-0.1 -> 58.12 | H5: =H6-0.1 -> 70.46 | I5: =I6-0.1 -> 62.26 | ... X5: =X6-0.1 -> 88.41 | AA5: =AA4+1 -> 1134
A6: 45572 | B6: =B7-0.1 -> 71.7 | C6: =C7-0.1 -> 64.1 | D6: =D7-0.1 -> 56.01 | E6: =E7-0.1 -> 60.47 | F6: =F7-0.1 -> 51.8 | G6: =G7-0.1 -> 58.22 | H6: =H7-0.1 -> 70.56 | I6: =I7-0.1 -> 62.36 | ... X6: =X7-0.1 -> 88.51 | AA6: =AA5+1 -> 1135
A7: 45573 | B7: =B8-0.1 -> 71.8 | C7: =C8-0.1 -> 64.2 | D7: =D8-0.1 -> 56.11 | E7: =E8-0.1 -> 60.57 | F7: =F8-0.1 -> 51.9 | G7: =G8-0.1 -> 58.32 | H7: =H8-0.1 -> 70.66 | I7: =I8-0.1 -> 62.46 | ... X7: =X8-0.1 -> 88.61 | AA7: =AA6+1 -> 1136
A8: 45574 | B8: =B9-0.1 -> 71.9 | C8: =C9-0.1 -> 64.3 | D8: =D9-0.1 -> 56.21 | E8: =E9-0.1 -> 60.67 | F8: =F9-0.1 -> 52 | G8: =G9-0.1 -> 58.42 | H8: =H9-0.1 -> 70.76 | I8: =I9-0.1 -> 62.56 | ... X8: =X9-0.1 -> 88.71 | AA8: =AA7+1 -> 1137
A9: 45575 | B9: =B10-0.1 -> 72 | C9: =C10-0.1 -> 64.4 | D9: =D10-0.1 -> 56.31 | E9: =E10-0.1 -> 60.77 | F9: =F10-0.1 -> 52.1 | G9: =G10-0.1 -> 58.52 | H9: =H10-0.1 -> 70.86 | I9: =I10-0.1 -> 62.66 | ... X9: =X10-0.1 -> 88.81 | AA9: =AA8+1 -> 1138
A10: 45576 | B10: =B11-0.1 -> 72.1 | C10: =C11-0.1 -> 64.5 | D10: =D11-0.1 -> 56.41 | E10: =E11-0.1 -> 60.87 | F10: =F11-0.1 -> 52.2 | G10: =G11-0.1 -> 58.62 | H10: =H11-0.1 -> 70.96 | I10: =I11-0.1 -> 62.76 | ... X10: =X11-0.1 -> 88.91 | AA10: =AA9+1 -> 1139
A11: 45577 | B11: =B12-0.1 -> 72.2 | C11: =C12-0.1 -> 64.6 | D11: =D12-0.1 -> 56.51 | E11: =E12-0.1 -> 60.97 | F11: =F12-0.1 -> 52.3 | G11: =G12-0.1 -> 58.72 | H11: =H12-0.1 -> 71.06 | I11: =I12-0.1 -> 62.86 | ... X11: =X12-0.1 -> 89.01 | AA11: =AA10+1 -> 1140
A12: 45578 | B12: =B13-0.1 -> 72.3 | C12: =C13-0.1 -> 64.7 | D12: =D13-0.1 -> 56.61 | E12: =E13-0.1 -> 61.07 | F12: =F13-0.1 -> 52.4 | G12: =G13-0.1 -> 58.82 | H12: =H13-0.1 -> 71.16 | I12: =I13-0.1 -> 62.96 | ... X12: =X13-0.1 -> 89.11 | AA12: =AA11+1 -> 1141
A13: 45579 | B13: =B14-0.1 -> 72.4 | C13: =C14-0.1 -> 64.8 | D13: =D14-0.1 -> 56.71 | E13: =E14-0.1 -> 61.17 | F13: =F14-0.1 -> 52.5 | G13: =G14-0.1 -> 58.92 | H13: =H14-0.1 -> 71.26 | I13: =I14-0.1 -> 63.06 | ... X13: =X14-0.1 -> 89.21 | AA13: =AA12+1 -> 1142
A14: 45580 | B14: =B15-0.1 -> 72.5 | C14: =C15-0.1 -> 64.9 | D14: =D15-0.1 -> 56.81 | E14: =E15-0.1 -> 61.27 | F14: =F15-0.1 -> 52.6 | G14: =G15-0.1 -> 59.02 | H14: =H15-0.1 -> 71.36 | I14: =I15-0.1 -> 63.16 | ... X14: =X15-0.1 -> 89.31 | AA14: =AA13+1 -> 1143
A15: 45581 | B15: 72.6 | C15: 65 | D15: 56.91 | E15: 61.37 | F15: 52.7 | G15: 59.12 | H15: 71.46 | I15: 63.26 | J15: 56.78 | K15: 58.99 | L15: 52.7 | M15: 98.9 | N15: 94.1 | O15: 88.4 | P15: 87.83 | Q15: 74.7 | R15: 91.76 | S15: 95.8 | T15: 91.75 | U15: 86 | V15: 84.8 | W15: 73 | X15: 89.41 | AA15: =AA14+1 -> 1144
A16: 45582 | B16: 71.9 | C16: 64.2 | D16: 55.65 | E16: 60.43 | F16: 51.69 | G16: 57.3 | H16: 69.7 | I16: 62.28 | J16: 55.2 | K16: 58.3 | L16: 51.22 | M16: 98.5 | N16: 93.89 | O16: 88.5 | P16: 86.7 | Q16: 75.3 | R16: 91.1 | S16: 95.7 | T16: 91.1 | U16: 85.25 | V16: 84.35 | W16: 73.25 | X16: 88.5 | AA16: =AA15+1 -> 1145
A17: 45583 | B17: 72.6 | C17: 63.9 | D17: 56 | E17: 60.4 | F17: 51.81 | G17: 58 | H17: 70.4 | I17: 62.12 | J17: 55.78 | K17: 59 | L17: 51 | M17: 99 | N17: 93.64 | O17: 88.99 | P17: 87.31 | Q17: 74.94 | R17: 90.88 | S17: 95.9 | T17: 91.2 | U17: 85.86 | V17: 84.5 | W17: 73.5 | X17: 88.3 | AA17: =AA16+1 -> 1146
A18: 45586 | B18: 71.5 | C18: 63.66 | D18: 55.36 | E18: 60.2 | F18: 51.35 | G18: 58 | H18: 69.6 | I18: 61.7 | J18: 55.5 | K18: 58.6 | L18: 51 | M18: 98.8 | N18: 93.62 | O18: 87.81 | P18: 86.8 | Q18: 75.75 | R18: 90.95 | S18: 96.4 | T18: 91.2 | U18: 85.95 | V18: 84.5 | W18: 73.5 | X18: 88.62 | AA18: =AA17+1 -> 1147
A19: 45587 | B19: 71.9 | C19: 63.55 | D19: 54.85 | E19: 59.57 | F19: 50.8 | G19: 57.46 | H19: 69.54 | I19: 61.8 | J19: 54.67 | K19: 58.05 | L19: 50.43 | M19: 98.3 | N19: 93.3 | O19: 88.53 | P19: 86.79 | Q19: 75.26 | R19: 90.6 | S19: 96.3 | T19: 91.25 | U19: 86.65 | V19: 84.6 | W19: 74 | X19: 88.35 | AA19: =AA18+1 -> 1148
A20: 45588 | B20: 71.5 | C20: 64 | D20: 55 | E20: 59.59 | F20: 51.3 | G20: 57.29 | H20: 68.84 | I20: 61.98 | J20: 55 | K20: 58.45 | L20: 50.4 | M20: 98.76 | N20: 93.38 | O20: 88.49 | P20: 87 | Q20: 76.23 | R20: 90.25 | S20: 96.75 | T20: 91.75 | U20: 86.21 | V20: 85 | W20: 74.25 | X20: 88.25 | AA20: =AA19+1 -> 1149
A21: 45589 | B21: 72.71 | C21: 65.56 | D21: 56.3 | E21: 60.93 | F21: 52.15 | G21: 58 | H21: 70.77 | I21: 63.5 | J21: 56.3 | K21: 59.3 | L21: 51.98 | M21: 99.18 | N21: 94.39 | O21: 88.61 | P21: 87.4 | Q21: 75.75 | R21: 91.04 | S21: 96.8 | T21: 92.5 | U21: 87.25 | V21: 85.75 | W21: 74.45 | X21: 89.2 | AA21: =AA20+1 -> 1150
A22: 45590 | B22: 72.71 | C22: 65.56 | D22: 56.3 | E22: 60.93 | F22: 52.15 | G22: 58 | H22: 70.77 | I22: 63.5 | J22: 56.3 | K22: 59.3 | L22: 51.98 | M22: 99.18 | N22: 94.39 | O22: 88.61 | P22: 87.4 | Q22: 75.75 | R22: 91.04 | S22: 96.8 | T22: 92.5 | U22: 87.25 | V22: 85.75 | W22: 74.45 | X22: 89.2 | AA22: =AA21+1 -> 1151
A23: 45593 | B23: 75.75 | C23: 69.05 | D23: 59.65 | E23: 64 | F23: 55.48 | G23: 60.99 | H23: 74 | I23: 67 | J23: 59.59 | K23: 62.98 | L23: 54.83 | M23: 100 | N23: 95.99 | O23: 91 | P23: 89.74 | Q23: 75.5 | R23: 92 | S23: 97.79 | T23: 93.81 | U23: 89 | V23: 87.85 | W23: 74 | X23: 90.06 | AA23: =AA22+1 -> 1152
A24: 45594 | B24: 74.16 | C24: 67.5 | D24: 58.7 | E24: 64.1 | F24: 54.78 | G24: 63 | H24: 72 | I24: 65.42 | J24: 58.9 | K24: 61.55 | L24: 54.66 | M24: 99.2 | N24: 95.02 | O24: 89.7 | P24: 88.85 | Q24: 74 | R24: 91.39 | S24: 97.08 | T24: 93.35 | U24: 88.5 | V24: 87.6 | W24: 74 | X24: 89.35 | AA24: =AA23+1 -> 1153
A25: 45595 | B25: 73.85 | C25: 67 | D25: 58.4 | E25: 63.34 | F25: 54.22 | G25: 60.56 | H25: 71.66 | I25: 64.49 | J25: 58.5 | K25: 61.72 | L25: 54.05 | M25: 95.9 | N25: 91.5 | O25: 86.5 | P25: 86.59 | Q25: 66.75 | R25: 91.6 | S25: 93.8 | T25: 90 | U25: 85 | V25: 84.2 | W25: 66 | X25: 89.75 | AA25: =AA24+1 -> 1154
A26: 45596 | B26: 73.02 | C26: 66.1 | D26: 58.23 | E26: 63 | F26: 53.9 | G26: 60.03 | H26: 72.19 | I26: 63.9 | J26: 58.2 | K26: 61.23 | L26: 53.95 | M26: 96.5 | N26: 91.5 | O26: 87.1 | P26: 85.93 | Q26: 67.25 | R26: 91.49 | S26: 94.81 | T26: 89.35 | U26: 85 | V26: 84 | W26: 65.5 | X26: 89.5 | AA26: =AA25+1 -> 1155
... A175: 45826 | B175: 75.06 | C175: 69.25 | D175: 67.73 | E175: 72 | F175: 62.62 | G175: 65.74 | H175: 73.48 | I175: 67.41 | J175: 67.57 | K175: 70.26 | L175: 61.85 | M175: 102 | N175: 97.53 | O175: 94.85 | P175: 95.4 | Q175: 9.4 | R175: 98.98 | S175: 101.2 | T175: 97.1 | U175: 94.51 | V175: 94.5 | W175: 9.359 | X175: 98.6 | AA175: =AA174+1 -> 1304
A176: 45827 | B176: 75.29 | C176: 69.12 | D176: 67.84 | E176: 72.03 | F176: 62.55 | G176: 65.49 | H176: 73.9 | I176: 67.23 | J176: 67.49 | K176: 70.45 | L176: 61.88 | M176: 100.8 | N176: 97.22 | O176: 94.97 | P176: 95.4 | R176: 98.69 | S176: 100.2 | T176: 96.76 | U176: 94.63 | V176: 94.7 | W176: 0 | X176: 98.69 | AA176: =AA175+1 -> 1305
A177: 45831 | B177: 75.04 | C177: 69.7 | D177: 68.36 | E177: 72.43 | F177: 62.75 | G177: 64.7 | H177: 73.7 | I177: 68.05 | J177: 68.13 | K177: 70.5 | L177: 61.8 | M177: 100.7 | N177: 97.91 | O177: 94.5 | P177: 95.4 | R177: 99.05 | S177: 99.4 | T177: 97.5 | U177: 94.2 | V177: 94.2 | W177: 0 | X177: 98.69 | AA177: =AA176+1 -> 1306
A178: 45832 | B178: 75.61 | C178: 70.99 | D178: 70.06 | E178: 73.98 | F178: 64.5 | G178: 66.16 | H178: 74.4 | I178: 69.03 | J178: 69.6 | K178: 72.4 | L178: 63.5 | N178: 97.55 | O178: 95.24 | P178: 94.8 | R178: 99.14 | T178: 97.56 | U178: 95.02 | V178: 94.65 | W178: 0 | X178: 98.69 | AA178: =AA177+1 -> 1307
A179: 45833 | B179: 76.6 | C179: 70.65 | D179: 69.6 | E179: 73.76 | F179: 64.08 | G179: 66.2 | H179: 74.69 | I179: 68.77 | J179: 69.1 | K179: 71.95 | L179: 62.99 | N179: 98.11 | O179: 95 | P179: 95 | R179: 99.29 | T179: 97.84 | U179: 94.7 | V179: 94.75 | W179: 0 | X179: 98.69 | AA179: =AA178+1 -> 1308
A180: 45834 | B180: 76.4 | C180: 71.09 | D180: 69.85 | E180: 74.4 | F180: 64.39 | G180: 66.49 | H180: 74.49 | I180: 69.24 | J180: 69.34 | K180: 72.47 | L180: 63.38 | N180: 98.35 | O180: 95.6 | P180: 95.15 | R180: 99.65 | T180: 98 | U180: 95 | V180: 95 | W180: 0 | X180: 98.69 | AA180: =AA179+1 -> 1309
A181: 45835 | B181: 76.99 | C181: 70.72 | D181: 70 | E181: 74.31 | F181: 64.9 | G181: 66.82 | H181: 74.62 | I181: 69.1 | J181: 69.48 | K181: 72.29 | L181: 64 | N181: 98.4 | O181: 95.53 | P181: 95.55 | R181: 99.65 | T181: 98.1 | U181: 95.14 | V181: 95.1 | W181: 0 | X181: 99.3 | Y181: 0 | Z181: 0 | AA181: =AA180+1 -> 1310
A182: 45838 | B182: 76 | C182: 70.23 | D182: 69.5 | E182: 73.97 | F182: 64.11 | G182: 65.91 | H182: 74.14 | I182: 68.45 | J182: 68.5 | K182: 71.43 | L182: 63.21 | N182: 98.99 | O182: 96.4 | P182: 95.8 | R182: 99.98 | T182: 98.19 | U182: 96 | V182: 95.74 | W182: 0 | X182: 99.72 | Y182: 80 | Z182: 84 | AA182: =AA181+1 -> 1311
A183: 45839 | B183: 75.79 | C183: 70.15 | D183: 69.35 | E183: 73.5 | F183: 64.11 | G183: 66.2 | H183: 73.75 | I183: 68.42 | J183: 68.54 | K183: 71.4 | L183: 62.96 | N183: 98.42 | O183: 96.13 | P183: 96.05 | R183: 99.6 | T183: 98.11 | U183: 96.05 | V183: 95.8 | W183: 0 | X183: 99.38 | Z183: 80.5 | AA183: =AA182+1 -> 1312
A184: 45840 | B184: 75.62 | C184: 70.34 | D184: 69.5 | E184: 73.55 | F184: 64.15 | G184: 66.03 | H184: 73.96 | I184: 68.86 | J184: 68.86 | K184: 71.7 | L184: 62.85 | N184: 98.85 | O184: 97.5 | P184: 96.63 | R184: 99.6 | T184: 98.55 | U184: 97.32 | V184: 96.35 | W184: 0 | X184: 99.5 | Y184: 82 | Z184: 82 | AA184: =AA183+1 -> 1313
A185: 45841 | B185: 76.24 | C185: 70.53 | D185: 69.46 | E185: 73.76 | F185: 64.41 | G185: 66.77 | H185: 74 | I185: 68.82 | J185: 68.65 | K185: 71.73 | L185: 63.48 | N185: 98.8 | O185: 97.7 | P185: 97.1 | R185: 99.75 | T185: 98.85 | U185: 97.6 | V185: 97 | W185: 0 | X185: 99.8 | Y185: 82.75 | Z185: 82.4 | AA185: =AA184+1 -> 1314
A186: 45842 | B186: 75.95 | C186: 70.6 | D186: 69.56 | E186: 74.24 | F186: 64.3 | G186: 66.21 | H186: 74.35 | I186: 68.95 | J186: 68.8 | K186: 72.03 | L186: 63.87 | N186: 99 | O186: 97.42 | P186: 97.41 | R186: 100 | T186: 98.99 | U186: 97.42 | V186: 97.23 | W186: 0 | X186: 100.2 | Y186: 83.75 | Z186: 83.5 | AA186: =AA185+1 -> 1315
A187: 45845 | B187: 74.44 | C187: 69.67 | D187: 68.6 | E187: 73.49 | F187: 63.25 | G187: 65.3 | H187: 73.45 | I187: 67.99 | J187: 67.71 | K187: 70.92 | L187: 62.38 | N187: 99.15 | O187: 96.89 | P187: 96.35 | R187: 100.7 | T187: 98.97 | U187: 96.82 | V187: 96.25 | W187: 0 | X187: 100.5 | Y187: 82.1 | Z187: 81.9 | AA187: =AA186+1 -> 1316
A188: 45846 | B188: 65.6 | C188: 61.6 | D188: 66.6 | E188: 70.54 | F188: 61.88 | G188: 61.36 | H188: 63.7 | I188: 59.95 | J188: 65.72 | K188: 68.25 | L188: 60.55 | N188: 99.37 | O188: 97.29 | P188: 96.85 | R188: 101.5 | T188: 99.25 | U188: 97 | V188: 96.7 | W188: 0 | X188: 101.3 | Y188: 82.98 | Z188: 82 | AA188: =AA187+1 -> 1317
...
